<?xml version="1.0" ?>
<!-- =================================================================================== -->
<!-- |    This document was autogenerated by xacro from /home/christos/catkin_ws/src/mini_project_kokas/src/mini_project/robots/argos.urdf.xacro | -->
<!-- |    EDITING THIS FILE BY HAND IS NOT RECOMMENDED                                 | -->
<!-- =================================================================================== -->
<robot name="argos">
  0
    
  <link name="base_link">
    <visual>
      <geometry>
        <mesh filename="package://mini_project/meshes/body.dae" scale="0.001 0.001 0.001"/>
      </geometry>
      <origin rpy="1.570796326794895 0 0" xyz="0.0 0.0 0.0"/>
    </visual>
    <collision>
      <geometry>
        <mesh filename="package://mini_project/meshes/body.dae" scale="0.001 0.001 0.001"/>
      </geometry>
      <origin rpy="1.570796326794895 0 0" xyz="0.0 0.0 0.0"/>
    </collision>
  </link>
  <link name="base_inertia">
    <inertial>
      <origin xyz="0 0 -0.00722624877"/>
      <mass value="22.44280461"/>
      <inertia ixx="0.23665589" ixy="0.0" ixz="0.0" iyy="0.96482316" iyz="0.0" izz="0.94492313"/>
    </inertial>
  </link>
  <joint name="base_link_to_base_inertia" type="fixed">
    <parent link="base_link"/>
    <child link="base_inertia"/>
    <origin rpy="0 0 0" xyz="0 0 0"/>
  </joint>
  <material name="zed_mat">
    <color rgba="0.8 0.8 0.8 0.8"/>
  </material>
  <material name="zedm_mat">
    <color rgba="0 0 0 0.9"/>
  </material>
  <material name="zed2_mat">
    <color rgba="0.25 0.25 0.25 0.99"/>
  </material>
  <material name="zed2i_mat">
    <color rgba="0.25 0.25 0.25 0.99"/>
  </material>
  <!-- Arguments -->
  <!-- Camera Center -->
  <joint name="camera_center_joint" type="fixed">
    <parent link="base_link"/>
    <child link="camera_center"/>
    <origin rpy="0.0 0.0 0.0" xyz="0.31 0.0 -0.14"/>
  </joint>
  <link name="camera_center">
    <visual>
      <origin rpy="0 0 0" xyz="0 0 0"/>
      <geometry>
        <mesh filename="package://mini_project/meshes/zed2.stl"/>
      </geometry>
      <material name="zed2_mat"/>
    </visual>
  </link>
  <!-- Left Camera -->
  <joint name="left_camera_joint" type="fixed">
    <parent link="camera_center"/>
    <child link="left_camera_frame"/>
    <origin rpy="0 0 0" xyz="0 0.06 0"/>
  </joint>
  <link name="left_camera_frame"/>
  <joint name="left_camera_optical_joint" type="fixed">
    <origin rpy="-1.5707963267948966 0.0 -1.5707963267948966" xyz="0 0 0"/>
    <parent link="left_camera_frame"/>
    <child link="left_camera_optical_frame"/>
  </joint>
  <link name="left_camera_optical_frame"/>
  <gazebo reference="left_camera_frame">
    <sensor name="stereo_camera" type="multicamera">
      <update_rate>30.0</update_rate>
      <camera name="left">
        <horizontal_fov>1.91986218</horizontal_fov>
        <vertical_fov>1.22173048</vertical_fov>
        <diagonal_fov>2.0943951</diagonal_fov>
        <image>
          <width>1920</width>
          <height>1080</height>
          <format>R8G8B8</format>
        </image>
        <clip>
          <near>0.02</near>
          <far>300</far>
        </clip>
        <noise>
          <type>gaussian</type>
          <mean>0.0</mean>
          <stddev>0.004</stddev>
        </noise>
      </camera>
      <camera name="right">
        <pose>0 -0.12 0 0 0 0</pose>
        <horizontal_fov>1.91986218</horizontal_fov>
        <vertical_fov>1.22173048</vertical_fov>
        <diagonal_fov>2.0943951</diagonal_fov>
        <image>
          <width>1920</width>
          <height>1080</height>
          <format>R8G8B8</format>
        </image>
        <clip>
          <near>0.02</near>
          <far>300</far>
        </clip>
        <noise>
          <type>gaussian</type>
          <mean>0.0</mean>
          <stddev>0.004</stddev>
        </noise>
      </camera>
      <plugin filename="libgazebo_ros_multicamera.so" name="stereo_camera_controller">
        <robotNamespace>argos</robotNamespace>
        <alwaysOn>true</alwaysOn>
        <updateRate>0.0</updateRate>
        <cameraName>camera</cameraName>
        <imageTopicName>image_raw</imageTopicName>
        <cameraInfoTopicName>camera_info</cameraInfoTopicName>
        <frameName>left_camera_optical_frame</frameName>
        <!--<rightFrameName>right_camera_optical_frame</rightFrameName>-->
        <hackBaseline>0.12</hackBaseline>
        <distortionK1>0.0</distortionK1>
        <distortionK2>0.0</distortionK2>
        <distortionK3>0.0</distortionK3>
        <distortionT1>0.0</distortionT1>
        <distortionT2>0.0</distortionT2>
      </plugin>
    </sensor>
  </gazebo>
  <gazebo>
    <plugin filename="libhector_gazebo_ros_imu.so" name="imu_controller">
      <updateRate>50.0</updateRate>
      <bodyName>imu_link</bodyName>
      <topicName>imu/data</topicName>
      <accelDrift>0.005 0.005 0.005</accelDrift>
      <frameId>argos/base_link</frameId>
      <accelGaussianNoise>0.005 0.005 0.005</accelGaussianNoise>
      <rateDrift>0.005 0.005 0.005 </rateDrift>
      <rateGaussianNoise>0.005 0.005 0.005 </rateGaussianNoise>
      <headingDrift>0.005</headingDrift>
      <headingGaussianNoise>0.005</headingGaussianNoise>
    </plugin>
  </gazebo>
  <link name="imu_link">
    <inertial>
      <mass value="0.001"/>
      <origin rpy="0 0 0" xyz="0 0 0"/>
      <inertia ixx="1e-09" ixy="0.0" ixz="0.0" iyy="1e-09" iyz="0.0" izz="1e-09"/>
    </inertial>
  </link>
  <joint name="imu_joint" type="fixed">
    <parent link="base_link"/>
    <child link="imu_link"/>
    <origin xyz="0.31 0.0 -0.12"/>
  </joint>
  <gazebo reference="base_link">
    <material>Gazebo/FlatBlack</material>
  </gazebo>
  <link name="LF_leg_roll">
    <inertial>
      <origin rpy="0 0 0" xyz="0.0016034699 0.19560047521 0.0"/>
      <mass value="1.1692019"/>
      <inertia ixx="0.00885796" ixy="-0.00035945" ixz="0.0" iyy="0.00270149" iyz="0.0" izz="0.00880666"/>
    </inertial>
    <visual>
      <geometry>
        <mesh filename="package://mini_project/meshes/thigh.dae" scale="0.001 0.001 0.001"/>
      </geometry>
      <origin rpy="1.570796326794895 0.0 1.570796326794895" xyz="0.0 0.0 0.0"/>
    </visual>
    <collision>
      <geometry>
        <mesh filename="package://mini_project/meshes/thigh.dae" scale="0.001 0.001 0.001"/>
      </geometry>
      <origin rpy="1.570796326794895 0.0 1.570796326794895" xyz="0.0 0.0 0.0"/>
    </collision>
  </link>
  <gazebo reference="LF_leg_roll">
    <material>Gazebo/Orange</material>
  </gazebo>
  <link name="LF_upper_leg">
    <inertial>
      <origin rpy="0 0 0" xyz="-1.2465e-07 8.927e-08 -0.19777343169"/>
      <mass value="1.45302356"/>
      <inertia ixx="0.03528932" ixy="0.0" ixz="0.0" iyy="0.03607343" iyz="0.0" izz="0.00156646"/>
    </inertial>
    <visual>
      <geometry>
        <mesh filename="package://mini_project/meshes/upper_leg.dae" scale="0.001 0.001 0.001"/>
      </geometry>
      <origin rpy="1.570796326794895 -1.570796326794895 0" xyz="0.0 0.0 0.0"/>
    </visual>
    <collision>
      <geometry>
        <mesh filename="package://mini_project/meshes/upper_leg.dae" scale="0.001 0.001 0.001"/>
      </geometry>
      <origin rpy="1.570796326794895 -1.570796326794895 0" xyz="0.0 0.0 0.0"/>
    </collision>
  </link>
  <gazebo reference="LF_upper_leg">
    <material>Gazebo/Green</material>
  </gazebo>
  <link name="LF_lower_leg">
    <inertial>
      <origin rpy="0 -0.2 0" xyz="-0.05466888228 2.713e-08 -0.15386388146"/>
      <mass value="0.87000291"/>
      <inertia ixx="0.04402853" ixy="0.0" ixz="0.00627914" iyy="0.04611436" iyz="0.0" izz="0.0026764"/>
    </inertial>
    <visual>
      <geometry>
        <mesh filename="package://mini_project/meshes/lower_leg.dae" scale="0.001 0.001 0.001"/>
      </geometry>
      <origin rpy="1.570796326794895 1.370796326794895 0" xyz="0 0.0 0"/>
    </visual>
    <collision>
      <geometry>
        <mesh filename="package://mini_project/meshes/lower_leg.dae" scale="0.001 0.001 0.001"/>
      </geometry>
      <origin rpy="1.570796326794895 1.370796326794895 0" xyz="0 0.0 0"/>
    </collision>
  </link>
  <gazebo reference="LF_lower_leg">
    <kp>100000.0</kp>
    <kd>1.0</kd>
    <mu1>1.0</mu1>
    <mu2>1.0</mu2>
    <maxVel>0.0</maxVel>
    <minDepth>0.001</minDepth>
    <material>Gazebo/Red</material>
  </gazebo>
  <link name="LF_foot"/>
  <joint name="LF_hip_joint" type="revolute">
    <parent link="base_link"/>
    <child link="LF_leg_roll"/>
    <axis xyz="1.0 0.0 0.0"/>
    <origin xyz="0.43 0.0 0.0"/>
    <limit effort="100" lower="-3.14159265358979" upper="3.14159265358979" velocity="10.0"/>
  </joint>
  <joint name="LF_upper_leg_joint" type="revolute">
    <parent link="LF_leg_roll"/>
    <child link="LF_upper_leg"/>
    <axis xyz="0.0 1.0  0.0"/>
    <origin xyz="0.0 0.233 0.0"/>
    <limit effort="100" lower="-3.14159265358979" upper="3.14159265358979" velocity="10.0"/>
  </joint>
  <joint name="LF_lower_leg_joint" type="revolute">
    <parent link="LF_upper_leg"/>
    <child link="LF_lower_leg"/>
    <axis xyz="0.0 1.0  0.0"/>
    <origin xyz="0.0 0.0 -0.45"/>
    <limit effort="100" lower="-3.14159265358979" upper="3.14159265358979" velocity="10.0"/>
  </joint>
  <joint name="LF_foot_joint" type="fixed">
    <parent link="LF_lower_leg"/>
    <child link="LF_foot"/>
    <origin xyz="0.0 0.0 -0.61"/>
  </joint>
  <gazebo reference="LF_hip_joint">
    <provideFeedback>true</provideFeedback>
  </gazebo>
  <gazebo reference="LF_upper_leg_joint">
    <provideFeedback>true</provideFeedback>
  </gazebo>
  <gazebo reference="LF_lower_leg_joint">
    <provideFeedback>true</provideFeedback>
  </gazebo>
  <transmission name="LF_hip_joint_trans">
    <type>transmission_interface/SimpleTransmission</type>
    <joint name="LF_hip_joint">
      <hardwareInterface>hardware_interface/EffortJointInterface</hardwareInterface>
    </joint>
    <actuator name="LF_hip_joint_motor">
      <mechanicalReduction>1</mechanicalReduction>
    </actuator>
  </transmission>
  <transmission name="LF_upper_leg_joint_trans">
    <type>transmission_interface/SimpleTransmission</type>
    <joint name="LF_upper_leg_joint">
      <hardwareInterface>hardware_interface/EffortJointInterface</hardwareInterface>
    </joint>
    <actuator name="LF_upper_leg_joint_motor">
      <mechanicalReduction>1</mechanicalReduction>
    </actuator>
  </transmission>
  <transmission name="LF_lower_leg_joint_trans">
    <type>transmission_interface/SimpleTransmission</type>
    <joint name="LF_lower_leg_joint">
      <hardwareInterface>hardware_interface/EffortJointInterface</hardwareInterface>
    </joint>
    <actuator name="LF_lower_joint_motor">
      <mechanicalReduction>1</mechanicalReduction>
    </actuator>
  </transmission>
  <link name="RF_leg_roll">
    <inertial>
      <origin rpy="0 0 0" xyz="-0.0016034699 -0.19560047521 0.0"/>
      <mass value="1.1692019"/>
      <inertia ixx="0.00885796" ixy="-0.00035945" ixz="0.0" iyy="0.00270149" iyz="0.0" izz="0.00880666"/>
    </inertial>
    <visual>
      <geometry>
        <mesh filename="package://mini_project/meshes/thigh.dae" scale="0.001 0.001 0.001"/>
      </geometry>
      <origin rpy="1.570796326794895 0.0 -1.570796326794895" xyz="0.0 0.0 0.0"/>
    </visual>
    <collision>
      <geometry>
        <mesh filename="package://mini_project/meshes/thigh.dae" scale="0.001 0.001 0.001"/>
      </geometry>
      <origin rpy="1.570796326794895 0.0 -1.570796326794895" xyz="0.0 0.0 0.0"/>
    </collision>
  </link>
  <gazebo reference="RF_leg_roll">
    <material>Gazebo/Orange</material>
  </gazebo>
  <link name="RF_upper_leg">
    <inertial>
      <origin rpy="0 0 0" xyz="-1.2465e-07 8.927e-08 -0.19777343169"/>
      <mass value="1.45302356"/>
      <inertia ixx="0.03528932" ixy="-0.0" ixz="0.0" iyy="0.03607343" iyz="-0.0" izz="0.00156646"/>
    </inertial>
    <visual>
      <geometry>
        <mesh filename="package://mini_project/meshes/upper_leg.dae" scale="0.001 0.001 0.001"/>
      </geometry>
      <origin rpy="1.570796326794895 -1.570796326794895 0" xyz="0.0 0.0 0.0"/>
    </visual>
    <collision>
      <geometry>
        <mesh filename="package://mini_project/meshes/upper_leg.dae" scale="0.001 0.001 0.001"/>
      </geometry>
      <origin rpy="1.570796326794895 -1.570796326794895 0" xyz="0.0 0.0 0.0"/>
    </collision>
  </link>
  <gazebo reference="RF_upper_leg">
    <material>Gazebo/Green</material>
  </gazebo>
  <link name="RF_lower_leg">
    <inertial>
      <origin rpy="0 -0.2 0" xyz="-0.05466888228 2.713e-08 -0.15386388146"/>
      <mass value="0.87000291"/>
      <inertia ixx="0.04402853" ixy="0.0" ixz="0.00627914" iyy="0.04611436" iyz="0.0" izz="0.0026764"/>
    </inertial>
    <visual>
      <geometry>
        <mesh filename="package://mini_project/meshes/lower_leg.dae" scale="0.001 0.001 0.001"/>
      </geometry>
      <origin rpy="1.570796326794895 1.370796326794895 0" xyz="0 0.0 0"/>
    </visual>
    <collision>
      <geometry>
        <mesh filename="package://mini_project/meshes/lower_leg.dae" scale="0.001 0.001 0.001"/>
      </geometry>
      <origin rpy="1.570796326794895 1.370796326794895 0" xyz="0 0.0 0"/>
    </collision>
  </link>
  <gazebo reference="RF_lower_leg">
    <kp>100000.0</kp>
    <kd>1.0</kd>
    <mu1>1.0</mu1>
    <mu2>1.0</mu2>
    <maxVel>0.0</maxVel>
    <minDepth>0.001</minDepth>
    <material>Gazebo/Red</material>
  </gazebo>
  <link name="RF_foot"/>
  <joint name="RF_hip_joint" type="revolute">
    <parent link="base_link"/>
    <child link="RF_leg_roll"/>
    <axis xyz="1.0 0.0 0.0"/>
    <origin xyz="0.43 0.0 0.0"/>
    <limit effort="100" lower="-3.14159265358979" upper="3.14159265358979" velocity="10.0"/>
  </joint>
  <joint name="RF_upper_leg_joint" type="revolute">
    <parent link="RF_leg_roll"/>
    <child link="RF_upper_leg"/>
    <axis xyz="0.0 1.0  0.0"/>
    <origin xyz="0.0 -0.233 0.0"/>
    <limit effort="100" lower="-3.14159265358979" upper="3.14159265358979" velocity="10.0"/>
  </joint>
  <joint name="RF_lower_leg_joint" type="revolute">
    <parent link="RF_upper_leg"/>
    <child link="RF_lower_leg"/>
    <axis xyz="0.0 1.0  0.0"/>
    <origin xyz="0.0 0.0 -0.45"/>
    <limit effort="100" lower="-3.14159265358979" upper="3.14159265358979" velocity="10.0"/>
  </joint>
  <joint name="RF_foot_joint" type="fixed">
    <parent link="RF_lower_leg"/>
    <child link="RF_foot"/>
    <origin xyz="0.0 0.0 -0.61"/>
  </joint>
  <gazebo reference="RF_hip_joint">
    <provideFeedback>true</provideFeedback>
  </gazebo>
  <gazebo reference="RF_upper_leg_joint">
    <provideFeedback>true</provideFeedback>
  </gazebo>
  <gazebo reference="RF_lower_leg_joint">
    <provideFeedback>true</provideFeedback>
  </gazebo>
  <transmission name="RF_hip_joint_trans">
    <type>transmission_interface/SimpleTransmission</type>
    <joint name="RF_hip_joint">
      <hardwareInterface>hardware_interface/EffortJointInterface</hardwareInterface>
    </joint>
    <actuator name="RF_hip_joint_motor">
      <mechanicalReduction>1</mechanicalReduction>
    </actuator>
  </transmission>
  <transmission name="RF_upper_leg_joint_trans">
    <type>transmission_interface/SimpleTransmission</type>
    <joint name="RF_upper_leg_joint">
      <hardwareInterface>hardware_interface/EffortJointInterface</hardwareInterface>
    </joint>
    <actuator name="RF_upper_leg_joint_motor">
      <mechanicalReduction>1</mechanicalReduction>
    </actuator>
  </transmission>
  <transmission name="RF_lower_leg_joint_trans">
    <type>transmission_interface/SimpleTransmission</type>
    <joint name="RF_lower_leg_joint">
      <hardwareInterface>hardware_interface/EffortJointInterface</hardwareInterface>
    </joint>
    <actuator name="RF_lower_joint_motor">
      <mechanicalReduction>1</mechanicalReduction>
    </actuator>
  </transmission>
  <link name="LH_leg_roll">
    <inertial>
      <origin rpy="0 0 0" xyz="0.0016034699 0.19560047521 0.0"/>
      <mass value="1.1692019"/>
      <inertia ixx="0.00885796" ixy="-0.00035945" ixz="0.0" iyy="0.00270149" iyz="0.0" izz="0.00880666"/>
    </inertial>
    <visual>
      <geometry>
        <mesh filename="package://mini_project/meshes/thigh.dae" scale="0.001 0.001 0.001"/>
      </geometry>
      <origin rpy="1.570796326794895 0.0 1.570796326794895" xyz="0.0 0.0 0.0"/>
    </visual>
    <collision>
      <geometry>
        <mesh filename="package://mini_project/meshes/thigh.dae" scale="0.001 0.001 0.001"/>
      </geometry>
      <origin rpy="1.570796326794895 0.0 1.570796326794895" xyz="0.0 0.0 0.0"/>
    </collision>
  </link>
  <gazebo reference="LH_leg_roll">
    <material>Gazebo/Orange</material>
  </gazebo>
  <link name="LH_upper_leg">
    <inertial>
      <origin rpy="0 0 0" xyz="-1.2465e-07 8.927e-08 -0.19777343169"/>
      <mass value="1.45302356"/>
      <inertia ixx="0.03528932" ixy="0.0" ixz="0.0" iyy="0.03607343" iyz="0.0" izz="0.00156646"/>
    </inertial>
    <visual>
      <geometry>
        <mesh filename="package://mini_project/meshes/upper_leg.dae" scale="0.001 0.001 0.001"/>
      </geometry>
      <origin rpy="1.570796326794895 -1.570796326794895 0" xyz="0.0 0.0 0.0"/>
    </visual>
    <collision>
      <geometry>
        <mesh filename="package://mini_project/meshes/upper_leg.dae" scale="0.001 0.001 0.001"/>
      </geometry>
      <origin rpy="1.570796326794895 -1.570796326794895 0" xyz="0.0 0.0 0.0"/>
    </collision>
  </link>
  <gazebo reference="LH_upper_leg">
    <material>Gazebo/Green</material>
  </gazebo>
  <link name="LH_lower_leg">
    <inertial>
      <origin rpy="0 -0.2 0" xyz="-0.05466888228 2.713e-08 -0.15386388146"/>
      <mass value="0.87000291"/>
      <inertia ixx="0.04402853" ixy="0.0" ixz="0.00627914" iyy="0.04611436" iyz="0.0" izz="0.0026764"/>
    </inertial>
    <visual>
      <geometry>
        <mesh filename="package://mini_project/meshes/lower_leg.dae" scale="0.001 0.001 0.001"/>
      </geometry>
      <origin rpy="1.570796326794895 1.370796326794895 0" xyz="0 0.0 0"/>
    </visual>
    <collision>
      <geometry>
        <mesh filename="package://mini_project/meshes/lower_leg.dae" scale="0.001 0.001 0.001"/>
      </geometry>
      <origin rpy="1.570796326794895 1.370796326794895 0" xyz="0 0.0 0"/>
    </collision>
  </link>
  <gazebo reference="LH_lower_leg">
    <kp>100000.0</kp>
    <kd>1.0</kd>
    <mu1>1.0</mu1>
    <mu2>1.0</mu2>
    <maxVel>0.0</maxVel>
    <minDepth>0.001</minDepth>
    <material>Gazebo/Red</material>
  </gazebo>
  <link name="LH_foot"/>
  <joint name="LH_hip_joint" type="revolute">
    <parent link="base_link"/>
    <child link="LH_leg_roll"/>
    <axis xyz="1.0 0.0 0.0"/>
    <origin xyz="-0.43 0.0 0.0"/>
    <limit effort="100" lower="-3.14159265358979" upper="3.14159265358979" velocity="10.0"/>
  </joint>
  <joint name="LH_upper_leg_joint" type="revolute">
    <parent link="LH_leg_roll"/>
    <child link="LH_upper_leg"/>
    <axis xyz="0.0 1.0  0.0"/>
    <origin xyz="0.0 0.233 0.0"/>
    <limit effort="100" lower="-3.14159265358979" upper="3.14159265358979" velocity="10.0"/>
  </joint>
  <joint name="LH_lower_leg_joint" type="revolute">
    <parent link="LH_upper_leg"/>
    <child link="LH_lower_leg"/>
    <axis xyz="0.0 1.0  0.0"/>
    <origin xyz="0.0 0.0 -0.45"/>
    <limit effort="100" lower="-3.14159265358979" upper="3.14159265358979" velocity="10.0"/>
  </joint>
  <joint name="LH_foot_joint" type="fixed">
    <parent link="LH_lower_leg"/>
    <child link="LH_foot"/>
    <origin xyz="0.0 0.0 -0.61"/>
  </joint>
  <gazebo reference="LH_hip_joint">
    <provideFeedback>true</provideFeedback>
  </gazebo>
  <gazebo reference="LH_upper_leg_joint">
    <provideFeedback>true</provideFeedback>
  </gazebo>
  <gazebo reference="LH_lower_leg_joint">
    <provideFeedback>true</provideFeedback>
  </gazebo>
  <transmission name="LH_hip_joint_trans">
    <type>transmission_interface/SimpleTransmission</type>
    <joint name="LH_hip_joint">
      <hardwareInterface>hardware_interface/EffortJointInterface</hardwareInterface>
    </joint>
    <actuator name="LH_hip_joint_motor">
      <mechanicalReduction>1</mechanicalReduction>
    </actuator>
  </transmission>
  <transmission name="LH_upper_leg_joint_trans">
    <type>transmission_interface/SimpleTransmission</type>
    <joint name="LH_upper_leg_joint">
      <hardwareInterface>hardware_interface/EffortJointInterface</hardwareInterface>
    </joint>
    <actuator name="LH_upper_leg_joint_motor">
      <mechanicalReduction>1</mechanicalReduction>
    </actuator>
  </transmission>
  <transmission name="LH_lower_leg_joint_trans">
    <type>transmission_interface/SimpleTransmission</type>
    <joint name="LH_lower_leg_joint">
      <hardwareInterface>hardware_interface/EffortJointInterface</hardwareInterface>
    </joint>
    <actuator name="LH_lower_joint_motor">
      <mechanicalReduction>1</mechanicalReduction>
    </actuator>
  </transmission>
  <link name="RH_leg_roll">
    <inertial>
      <origin rpy="0 0 0" xyz="-0.0016034699 -0.19560047521 0.0"/>
      <mass value="1.1692019"/>
      <inertia ixx="0.00885796" ixy="-0.00035945" ixz="0.0" iyy="0.00270149" iyz="0.0" izz="0.00880666"/>
    </inertial>
    <visual>
      <geometry>
        <mesh filename="package://mini_project/meshes/thigh.dae" scale="0.001 0.001 0.001"/>
      </geometry>
      <origin rpy="1.570796326794895 0.0 -1.570796326794895" xyz="0.0 0.0 0.0"/>
    </visual>
    <collision>
      <geometry>
        <mesh filename="package://mini_project/meshes/thigh.dae" scale="0.001 0.001 0.001"/>
      </geometry>
      <origin rpy="1.570796326794895 0.0 -1.570796326794895" xyz="0.0 0.0 0.0"/>
    </collision>
  </link>
  <gazebo reference="RH_leg_roll">
    <material>Gazebo/Orange</material>
  </gazebo>
  <link name="RH_upper_leg">
    <inertial>
      <origin rpy="0 0 0" xyz="-1.2465e-07 8.927e-08 -0.19777343169"/>
      <mass value="1.45302356"/>
      <inertia ixx="0.03528932" ixy="-0.0" ixz="0.0" iyy="0.03607343" iyz="-0.0" izz="0.00156646"/>
    </inertial>
    <visual>
      <geometry>
        <mesh filename="package://mini_project/meshes/upper_leg.dae" scale="0.001 0.001 0.001"/>
      </geometry>
      <origin rpy="1.570796326794895 -1.570796326794895 0" xyz="0.0 0.0 0.0"/>
    </visual>
    <collision>
      <geometry>
        <mesh filename="package://mini_project/meshes/upper_leg.dae" scale="0.001 0.001 0.001"/>
      </geometry>
      <origin rpy="1.570796326794895 -1.570796326794895 0" xyz="0.0 0.0 0.0"/>
    </collision>
  </link>
  <gazebo reference="RH_upper_leg">
    <material>Gazebo/Green</material>
  </gazebo>
  <link name="RH_lower_leg">
    <inertial>
      <origin rpy="0 -0.2 0" xyz="-0.05466888228 2.713e-08 -0.15386388146"/>
      <mass value="0.87000291"/>
      <inertia ixx="0.04402853" ixy="0.0" ixz="0.00627914" iyy="0.04611436" iyz="0.0" izz="0.0026764"/>
    </inertial>
    <visual>
      <geometry>
        <mesh filename="package://mini_project/meshes/lower_leg.dae" scale="0.001 0.001 0.001"/>
      </geometry>
      <origin rpy="1.570796326794895 1.370796326794895 0" xyz="0 0.0 0"/>
    </visual>
    <collision>
      <geometry>
        <mesh filename="package://mini_project/meshes/lower_leg.dae" scale="0.001 0.001 0.001"/>
      </geometry>
      <origin rpy="1.570796326794895 1.370796326794895 0" xyz="0 0.0 0"/>
    </collision>
  </link>
  <gazebo reference="RH_lower_leg">
    <kp>100000.0</kp>
    <kd>1.0</kd>
    <mu1>1.0</mu1>
    <mu2>1.0</mu2>
    <maxVel>0.0</maxVel>
    <minDepth>0.001</minDepth>
    <material>Gazebo/Red</material>
  </gazebo>
  <link name="RH_foot"/>
  <joint name="RH_hip_joint" type="revolute">
    <parent link="base_link"/>
    <child link="RH_leg_roll"/>
    <axis xyz="1.0 0.0 0.0"/>
    <origin xyz="-0.43 0.0 0.0"/>
    <limit effort="100" lower="-3.14159265358979" upper="3.14159265358979" velocity="10.0"/>
  </joint>
  <joint name="RH_upper_leg_joint" type="revolute">
    <parent link="RH_leg_roll"/>
    <child link="RH_upper_leg"/>
    <axis xyz="0.0 1.0  0.0"/>
    <origin xyz="0.0 -0.233 0.0"/>
    <limit effort="100" lower="-3.14159265358979" upper="3.14159265358979" velocity="10.0"/>
  </joint>
  <joint name="RH_lower_leg_joint" type="revolute">
    <parent link="RH_upper_leg"/>
    <child link="RH_lower_leg"/>
    <axis xyz="0.0 1.0  0.0"/>
    <origin xyz="0.0 0.0 -0.45"/>
    <limit effort="100" lower="-3.14159265358979" upper="3.14159265358979" velocity="10.0"/>
  </joint>
  <joint name="RH_foot_joint" type="fixed">
    <parent link="RH_lower_leg"/>
    <child link="RH_foot"/>
    <origin xyz="0.0 0.0 -0.61"/>
  </joint>
  <gazebo reference="RH_hip_joint">
    <provideFeedback>true</provideFeedback>
  </gazebo>
  <gazebo reference="RH_upper_leg_joint">
    <provideFeedback>true</provideFeedback>
  </gazebo>
  <gazebo reference="RH_lower_leg_joint">
    <provideFeedback>true</provideFeedback>
  </gazebo>
  <transmission name="RH_hip_joint_trans">
    <type>transmission_interface/SimpleTransmission</type>
    <joint name="RH_hip_joint">
      <hardwareInterface>hardware_interface/EffortJointInterface</hardwareInterface>
    </joint>
    <actuator name="RH_hip_joint_motor">
      <mechanicalReduction>1</mechanicalReduction>
    </actuator>
  </transmission>
  <transmission name="RH_upper_leg_joint_trans">
    <type>transmission_interface/SimpleTransmission</type>
    <joint name="RH_upper_leg_joint">
      <hardwareInterface>hardware_interface/EffortJointInterface</hardwareInterface>
    </joint>
    <actuator name="RH_upper_leg_joint_motor">
      <mechanicalReduction>1</mechanicalReduction>
    </actuator>
  </transmission>
  <transmission name="RH_lower_leg_joint_trans">
    <type>transmission_interface/SimpleTransmission</type>
    <joint name="RH_lower_leg_joint">
      <hardwareInterface>hardware_interface/EffortJointInterface</hardwareInterface>
    </joint>
    <actuator name="RH_lower_joint_motor">
      <mechanicalReduction>1</mechanicalReduction>
    </actuator>
  </transmission>
  <!-- <xacro:manipulator base_name="base_link"/> -->
  <gazebo>
    <plugin filename="libgazebo_ros_p3d.so" name="p3d_base_controller">
      <alwaysOn>true</alwaysOn>
      <updateRate>50.0</updateRate>
      <bodyName>base_link</bodyName>
      <topicName>odom/ground_truth</topicName>
      <gaussianNoise>0.001</gaussianNoise>
      <frameName>world</frameName>
      <xyzOffsets>0 0 0</xyzOffsets>
      <rpyOffsets>0 0 0</rpyOffsets>
    </plugin>
  </gazebo>
  <gazebo>
    <plugin filename="libgazebo_ros_control.so" name="gazebo_ros_control">
      <legacyModeNS>true</legacyModeNS>
    </plugin>
  </gazebo>
</robot>

