<?xml version="1.0" ?>
<!-- =================================================================================== -->
<!-- |    This document was autogenerated by xacro from argos_depth.urdf.xacro         | -->
<!-- |    EDITING THIS FILE BY HAND IS NOT RECOMMENDED                                 | -->
<!-- =================================================================================== -->
<robot name="argos">
  <link name="base_link">
    <visual>
      <geometry>
        <mesh filename="package://mini_project/meshes/body.dae" scale="0.001 0.001 0.001"/>
      </geometry>
      <origin rpy="1.570796326794895 0 0" xyz="0.0 0.0 0.0"/>
    </visual>
    <collision>
      <geometry>
        <mesh filename="package://mini_project/meshes/body.dae" scale="0.001 0.001 0.001"/>
      </geometry>
      <origin rpy="1.570796326794895 0 0" xyz="0.0 0.0 0.0"/>
    </collision>
  </link>
  <link name="base_inertia">
    <inertial>
      <origin xyz="0 0 -0.00722624877"/>
      <mass value="44.88560357849"/>
      <inertia ixx="0.4733117048862877" ixy="-1.187694189e-08" ixz="3e-17" iyy="1.9296460018476334" iyz="-2e-17" izz="1.8898459005293233"/>
    </inertial>
  </link>
  <joint name="base_link_to_base_inertia" type="fixed">
    <parent link="base_link"/>
    <child link="base_inertia"/>
    <origin rpy="0 0 0" xyz="0 0 0"/>
  </joint>
  <material name="zed_mat">
    <color rgba="0.8 0.8 0.8 0.8"/>
  </material>
  <material name="zedm_mat">
    <color rgba="0 0 0 0.9"/>
  </material>
  <material name="zed2_mat">
    <color rgba="0.25 0.25 0.25 0.99"/>
  </material>
  <material name="zed2i_mat">
    <color rgba="0.25 0.25 0.25 0.99"/>
  </material>
  <!-- Arguments -->
  <!-- Camera Center -->
  <joint name="camera_center_joint" type="fixed">
    <parent link="base_link"/>
    <child link="camera_center"/>
    <origin rpy="0.0 0.0 0.0" xyz="0.31 0.0 -0.14"/>
  </joint>
  <link name="camera_center">
    <visual>
      <origin rpy="0 0 0" xyz="0 0 0"/>
      <geometry>
        <mesh filename="package://mini_project/meshes/zed2.stl"/>
      </geometry>
      <material name="zed2_mat"/>
    </visual>
  </link>
  <!-- Left Camera -->
  <joint name="left_camera_joint" type="fixed">
    <parent link="camera_center"/>
    <child link="left_camera_frame"/>
    <origin rpy="0 0 0" xyz="0 0.06 0"/>
  </joint>
  <link name="left_camera_frame"/>
  <joint name="left_camera_optical_joint" type="fixed">
    <origin rpy="-1.5707963267948966 0.0 -1.5707963267948966" xyz="0 0 0"/>
    <parent link="left_camera_frame"/>
    <child link="left_camera_optical_frame"/>
  </joint>
  <link name="left_camera_optical_frame"/>
  <gazebo reference="left_camera_frame">
    <sensor name="openni_camera_camera" type="depth">
      <always_on>1</always_on>
      <visualize>true</visualize>
      <camera>
        <horizontal_fov>1.91986218</horizontal_fov>
        <vertical_fov>1.22173048</vertical_fov>
        <diagonal_fov>2.0943951</diagonal_fov>
        <image>
          <width>1920</width>
          <height>1080</height>
          <format>R8G8B8</format>
        </image>
        <clip>
          <near>0.1</near>
          <far>25.0</far>
        </clip>
      </camera>
      <plugin filename="libgazebo_ros_openni_kinect.so" name="camera_plugin">
        <robotNamespace>argos</robotNamespace>
        <baseline>0.2</baseline>
        <alwaysOn>true</alwaysOn>
        <!-- Keep this zero, update_rate in the parent <sensor> tag
                will control the frame rate. -->
        <updateRate>0.0</updateRate>
        <cameraName>depth_camera</cameraName>
        <imageTopicName>/depth/image_rect_color</imageTopicName>
        <cameraInfoTopicName>/argos/depth/camera_info </cameraInfoTopicName>
        <depthImageTopicName>/argos/depth/depth_registered</depthImageTopicName>
        <depthImageCameraInfoTopicName>/argos/depth/image_raw/camera_info</depthImageCameraInfoTopicName>
        <pointCloudTopicName>/argos/depth/point_cloud/cloud_registered </pointCloudTopicName>
        <frameName>left_camera_optical_frame</frameName>
        <pointCloudCutoff>0.4</pointCloudCutoff>
        <!-- does nothing it seems
            <pointCloudCutoffMax>20.0</pointCloudCutoffMax> -->
        <distortionK1>0</distortionK1>
        <distortionK2>0</distortionK2>
        <distortionK3>0</distortionK3>
        <distortionT1>0</distortionT1>
        <distortionT2>0</distortionT2>
        <CxPrime>0</CxPrime>
        <Cx>0</Cx>
        <Cy>0</Cy>
        <focalLength>0</focalLength>
        <hackBaseline>0</hackBaseline>
      </plugin>
    </sensor>
    <sensor name="stereo_camera" type="multicamera">
      <update_rate>30.0</update_rate>
      <camera name="left">
        <horizontal_fov>1.91986218</horizontal_fov>
        <vertical_fov>1.22173048</vertical_fov>
        <diagonal_fov>2.0943951</diagonal_fov>
        <image>
          <width>1920</width>
          <height>1080</height>
          <format>R8G8B8</format>
        </image>
        <clip>
          <near>0.02</near>
          <far>300</far>
        </clip>
        <noise>
          <type>gaussian</type>
          <mean>0.0</mean>
          <stddev>0.004</stddev>
        </noise>
      </camera>
      <camera name="right">
        <pose>0 -0.12 0 0 0 0</pose>
        <horizontal_fov>1.91986218</horizontal_fov>
        <vertical_fov>1.22173048</vertical_fov>
        <diagonal_fov>2.0943951</diagonal_fov>
        <image>
          <width>1920</width>
          <height>1080</height>
          <format>R8G8B8</format>
        </image>
        <clip>
          <near>0.02</near>
          <far>300</far>
        </clip>
        <noise>
          <type>gaussian</type>
          <mean>0.0</mean>
          <stddev>0.004</stddev>
        </noise>
      </camera>
      <plugin filename="libgazebo_ros_multicamera.so" name="stereo_camera_controller">
        <robotNamespace>argos</robotNamespace>
        <alwaysOn>true</alwaysOn>
        <updateRate>0.0</updateRate>
        <cameraName>camera</cameraName>
        <imageTopicName>image_raw</imageTopicName>
        <cameraInfoTopicName>camera_info</cameraInfoTopicName>
        <frameName>left_camera_optical_frame</frameName>
        <!--<rightFrameName>right_camera_optical_frame</rightFrameName>-->
        <hackBaseline>0.12</hackBaseline>
        <distortionK1>0.0</distortionK1>
        <distortionK2>0.0</distortionK2>
        <distortionK3>0.0</distortionK3>
        <distortionT1>0.0</distortionT1>
        <distortionT2>0.0</distortionT2>
      </plugin>
    </sensor>
  </gazebo>
  <gazebo>
    <plugin filename="libhector_gazebo_ros_imu.so" name="imu_controller">
      <updateRate>50.0</updateRate>
      <bodyName>imu_link</bodyName>
      <topicName>imu/data</topicName>
      <accelDrift>0.005 0.005 0.005</accelDrift>
      <frameId>argos/base_link</frameId>
      <accelGaussianNoise>0.005 0.005 0.005</accelGaussianNoise>
      <rateDrift>0.005 0.005 0.005 </rateDrift>
      <rateGaussianNoise>0.005 0.005 0.005 </rateGaussianNoise>
      <headingDrift>0.005</headingDrift>
      <headingGaussianNoise>0.005</headingGaussianNoise>
    </plugin>
  </gazebo>
  <link name="imu_link">
    <inertial>
      <mass value="0.001"/>
      <origin rpy="0 0 0" xyz="0 0 0"/>
      <inertia ixx="1e-09" ixy="0.0" ixz="0.0" iyy="1e-09" iyz="0.0" izz="1e-09"/>
    </inertial>
  </link>
  <joint name="imu_joint" type="fixed">
    <parent link="base_link"/>
    <child link="imu_link"/>
    <origin xyz="0.31 0.0 -0.12"/>
  </joint>
  <gazebo reference="base_link">
    <material>Gazebo/FlatBlack</material>
  </gazebo>
  <link name="LF_leg_roll">
    <inertial>
      <origin rpy="0 0 0" xyz="0.0016034699 0.19560047521 0.0"/>
      <mass value="2.33840380361"/>
      <inertia ixx="0.01771591024567954" ixy="-0.00071891013320325" ixz="5.15073e-11" iyy="0.00540298667216859" iyz="1.6635487e-10" izz="0.01761332943089841"/>
    </inertial>
    <visual>
      <geometry>
        <mesh filename="package://mini_project/meshes/thigh.dae" scale="0.001 0.001 0.001"/>
      </geometry>
      <origin rpy="1.570796326794895 0.0 1.570796326794895" xyz="0.0 0.0 0.0"/>
    </visual>
    <collision>
      <geometry>
        <mesh filename="package://mini_project/meshes/thigh.dae" scale="0.001 0.001 0.001"/>
      </geometry>
      <origin rpy="1.570796326794895 0.0 1.570796326794895" xyz="0.0 0.0 0.0"/>
    </collision>
  </link>
  <gazebo reference="LF_leg_roll">
    <material>Gazebo/Orange</material>
  </gazebo>
  <link name="LF_upper_leg">
    <inertial>
      <origin rpy="1.570796326794895 0 1.570796326794895" xyz="-1.2465e-07 8.927e-08 -0.19777343169"/>
      <mass value="2.90604711841"/>
      <inertia ixx="0.07057863001314926" ixy="2.7932686e-10" ixz="-3.7129365e-10" iyy="0.07214686311642775" iyz="-6.9735152e-09" izz="0.0031329294799625"/>
    </inertial>
    <visual>
      <geometry>
        <mesh filename="package://mini_project/meshes/upper_leg.dae" scale="0.001 0.001 0.001"/>
      </geometry>
      <origin rpy="1.570796326794895 -1.570796326794895 0" xyz="0.0 0.0 0.0"/>
    </visual>
    <collision>
      <geometry>
        <mesh filename="package://mini_project/meshes/upper_leg.dae" scale="0.001 0.001 0.001"/>
      </geometry>
      <origin rpy="1.570796326794895 -1.570796326794895 0" xyz="0.0 0.0 0.0"/>
    </collision>
  </link>
  <gazebo reference="LF_upper_leg">
    <material>Gazebo/Green</material>
  </gazebo>
  <link name="LF_lower_leg">
    <inertial>
      <origin rpy="0 -0.2 0" xyz="-0.05466888228 2.713e-08 -0.15386388146"/>
      <mass value="1.81736381294"/>
      <inertia ixx="0.0907939555791539" ixy="-1.255242645e-08" ixz="0.01304754928405628" iyy="0.0951071480397549" iyz="-6.39667712e-09" izz="0.00552232540194871"/>
    </inertial>
    <visual>
      <geometry>
        <mesh filename="package://mini_project/meshes/lower_leg.dae" scale="0.001 0.001 0.001"/>
      </geometry>
      <origin rpy="1.570796326794895 1.370796326794895 0" xyz="0 0.0 0"/>
    </visual>
    <collision>
      <geometry>
        <mesh filename="package://mini_project/meshes/lower_leg.dae" scale="0.001 0.001 0.001"/>
      </geometry>
      <origin rpy="1.570796326794895 1.370796326794895 0" xyz="0 0.0 0"/>
    </collision>
  </link>
  <gazebo reference="LF_lower_leg">
    <kp>100000.0</kp>
    <kd>1.0</kd>
    <mu1>1.0</mu1>
    <mu2>1.0</mu2>
    <maxVel>0.0</maxVel>
    <minDepth>0.001</minDepth>
    <material>Gazebo/Red</material>
  </gazebo>
  <link name="LF_foot"/>
  <joint name="LF_hip_joint" type="revolute">
    <parent link="base_link"/>
    <child link="LF_leg_roll"/>
    <axis xyz="1.0 0.0 0.0"/>
    <origin xyz="0.43 0.0 0.0"/>
    <limit effort="250" lower="-3.14159265358979" upper="3.14159265358979" velocity="5.0"/>
  </joint>
  <joint name="LF_upper_leg_joint" type="revolute">
    <parent link="LF_leg_roll"/>
    <child link="LF_upper_leg"/>
    <axis xyz="0.0 1.0  0.0"/>
    <origin xyz="0.0 0.233 0.0"/>
    <limit effort="250" lower="-3.14159265358979" upper="3.14159265358979" velocity="5.0"/>
  </joint>
  <joint name="LF_lower_leg_joint" type="revolute">
    <parent link="LF_upper_leg"/>
    <child link="LF_lower_leg"/>
    <axis xyz="0.0 1.0  0.0"/>
    <origin xyz="0.0 0.0 -0.45"/>
    <limit effort="250" lower="-3.14159265358979" upper="3.14159265358979" velocity="2.0"/>
  </joint>
  <joint name="LF_foot_joint" type="fixed">
    <parent link="LF_lower_leg"/>
    <child link="LF_foot"/>
    <origin xyz="0.0 0.0 -0.61"/>
  </joint>
  <gazebo reference="LF_hip_joint">
    <provideFeedback>true</provideFeedback>
  </gazebo>
  <gazebo reference="LF_upper_leg_joint">
    <provideFeedback>true</provideFeedback>
  </gazebo>
  <gazebo reference="LF_lower_leg_joint">
    <provideFeedback>true</provideFeedback>
  </gazebo>
  <transmission name="LF_hip_joint_trans">
    <type>transmission_interface/SimpleTransmission</type>
    <joint name="LF_hip_joint">
      <hardwareInterface>hardware_interface/EffortJointInterface</hardwareInterface>
    </joint>
    <actuator name="LF_hip_joint_motor">
      <mechanicalReduction>1</mechanicalReduction>
    </actuator>
  </transmission>
  <transmission name="LF_upper_leg_joint_trans">
    <type>transmission_interface/SimpleTransmission</type>
    <joint name="LF_upper_leg_joint">
      <hardwareInterface>hardware_interface/EffortJointInterface</hardwareInterface>
    </joint>
    <actuator name="LF_upper_leg_joint_motor">
      <mechanicalReduction>1</mechanicalReduction>
    </actuator>
  </transmission>
  <transmission name="LF_lower_leg_joint_trans">
    <type>transmission_interface/SimpleTransmission</type>
    <joint name="LF_lower_leg_joint">
      <hardwareInterface>hardware_interface/EffortJointInterface</hardwareInterface>
    </joint>
    <actuator name="LF_lower_joint_motor">
      <mechanicalReduction>1</mechanicalReduction>
    </actuator>
  </transmission>
  <link name="RF_leg_roll">
    <inertial>
      <origin rpy="0 0 0" xyz="-0.0016034699 -0.19560047521 0.0"/>
      <mass value="2.33840380361"/>
      <inertia ixx="0.01771591024567954" ixy="-0.00071891013320325" ixz="5.15073e-11" iyy="0.00540298667216859" iyz="1.6635487e-10" izz="0.01761332943089841"/>
    </inertial>
    <visual>
      <geometry>
        <mesh filename="package://mini_project/meshes/thigh.dae" scale="0.001 0.001 0.001"/>
      </geometry>
      <origin rpy="1.570796326794895 0.0 -1.570796326794895" xyz="0.0 0.0 0.0"/>
    </visual>
    <collision>
      <geometry>
        <mesh filename="package://mini_project/meshes/thigh.dae" scale="0.001 0.001 0.001"/>
      </geometry>
      <origin rpy="1.570796326794895 0.0 -1.570796326794895" xyz="0.0 0.0 0.0"/>
    </collision>
  </link>
  <gazebo reference="RF_leg_roll">
    <material>Gazebo/Orange</material>
  </gazebo>
  <link name="RF_upper_leg">
    <inertial>
      <origin rpy="1.570796326794895 0 1.570796326794895" xyz="-1.2465e-07 8.927e-08 -0.19777343169"/>
      <mass value="2.90604711841"/>
      <inertia ixx="0.07057863001314926" ixy="-2.7932686e-10" ixz="-3.7129365e-10" iyy="0.07214686311642775" iyz="6.9735152e-09" izz="0.0031329294799625"/>
    </inertial>
    <visual>
      <geometry>
        <mesh filename="package://mini_project/meshes/upper_leg.dae" scale="0.001 0.001 0.001"/>
      </geometry>
      <origin rpy="1.570796326794895 -1.570796326794895 0" xyz="0.0 0.0 0.0"/>
    </visual>
    <collision>
      <geometry>
        <mesh filename="package://mini_project/meshes/upper_leg.dae" scale="0.001 0.001 0.001"/>
      </geometry>
      <origin rpy="1.570796326794895 -1.570796326794895 0" xyz="0.0 0.0 0.0"/>
    </collision>
  </link>
  <gazebo reference="RF_upper_leg">
    <material>Gazebo/Green</material>
  </gazebo>
  <link name="RF_lower_leg">
    <inertial>
      <origin rpy="0 -0.2 0" xyz="-0.05466888228 2.713e-08 -0.15386388146"/>
      <mass value="1.81736381294"/>
      <inertia ixx="0.0907939555791539" ixy="-1.255242645e-08" ixz="0.01304754928405628" iyy="0.0951071480397549" iyz="-6.39667712e-09" izz="0.00552232540194871"/>
    </inertial>
    <visual>
      <geometry>
        <mesh filename="package://mini_project/meshes/lower_leg.dae" scale="0.001 0.001 0.001"/>
      </geometry>
      <origin rpy="1.570796326794895 1.370796326794895 0" xyz="0 0.0 0"/>
    </visual>
    <collision>
      <geometry>
        <mesh filename="package://mini_project/meshes/lower_leg.dae" scale="0.001 0.001 0.001"/>
      </geometry>
      <origin rpy="1.570796326794895 1.370796326794895 0" xyz="0 0.0 0"/>
    </collision>
  </link>
  <gazebo reference="RF_lower_leg">
    <kp>100000.0</kp>
    <kd>1.0</kd>
    <mu1>1.0</mu1>
    <mu2>1.0</mu2>
    <maxVel>0.0</maxVel>
    <minDepth>0.001</minDepth>
    <material>Gazebo/Red</material>
  </gazebo>
  <link name="RF_foot"/>
  <joint name="RF_hip_joint" type="revolute">
    <parent link="base_link"/>
    <child link="RF_leg_roll"/>
    <axis xyz="1.0 0.0 0.0"/>
    <origin xyz="0.43 0.0 0.0"/>
    <limit effort="250" lower="-3.14159265358979" upper="3.14159265358979" velocity="5.0"/>
  </joint>
  <joint name="RF_upper_leg_joint" type="revolute">
    <parent link="RF_leg_roll"/>
    <child link="RF_upper_leg"/>
    <axis xyz="0.0 1.0  0.0"/>
    <origin xyz="0.0 -0.233 0.0"/>
    <limit effort="250" lower="-3.14159265358979" upper="3.14159265358979" velocity="5.0"/>
  </joint>
  <joint name="RF_lower_leg_joint" type="revolute">
    <parent link="RF_upper_leg"/>
    <child link="RF_lower_leg"/>
    <axis xyz="0.0 1.0  0.0"/>
    <origin xyz="0.0 0.0 -0.45"/>
    <limit effort="250" lower="-3.14159265358979" upper="3.14159265358979" velocity="2.0"/>
  </joint>
  <joint name="RF_foot_joint" type="fixed">
    <parent link="RF_lower_leg"/>
    <child link="RF_foot"/>
    <origin xyz="0.0 0.0 -0.61"/>
  </joint>
  <gazebo reference="RF_hip_joint">
    <provideFeedback>true</provideFeedback>
  </gazebo>
  <gazebo reference="RF_upper_leg_joint">
    <provideFeedback>true</provideFeedback>
  </gazebo>
  <gazebo reference="RF_lower_leg_joint">
    <provideFeedback>true</provideFeedback>
  </gazebo>
  <transmission name="RF_hip_joint_trans">
    <type>transmission_interface/SimpleTransmission</type>
    <joint name="RF_hip_joint">
      <hardwareInterface>hardware_interface/EffortJointInterface</hardwareInterface>
    </joint>
    <actuator name="RF_hip_joint_motor">
      <mechanicalReduction>1</mechanicalReduction>
    </actuator>
  </transmission>
  <transmission name="RF_upper_leg_joint_trans">
    <type>transmission_interface/SimpleTransmission</type>
    <joint name="RF_upper_leg_joint">
      <hardwareInterface>hardware_interface/EffortJointInterface</hardwareInterface>
    </joint>
    <actuator name="RF_upper_leg_joint_motor">
      <mechanicalReduction>1</mechanicalReduction>
    </actuator>
  </transmission>
  <transmission name="RF_lower_leg_joint_trans">
    <type>transmission_interface/SimpleTransmission</type>
    <joint name="RF_lower_leg_joint">
      <hardwareInterface>hardware_interface/EffortJointInterface</hardwareInterface>
    </joint>
    <actuator name="RF_lower_joint_motor">
      <mechanicalReduction>1</mechanicalReduction>
    </actuator>
  </transmission>
  <link name="LH_leg_roll">
    <inertial>
      <origin rpy="0 0 0" xyz="0.0016034699 0.19560047521 0.0"/>
      <mass value="2.33840380361"/>
      <inertia ixx="0.01771591024567954" ixy="-0.00071891013320325" ixz="5.15073e-11" iyy="0.00540298667216859" iyz="1.6635487e-10" izz="0.01761332943089841"/>
    </inertial>
    <visual>
      <geometry>
        <mesh filename="package://mini_project/meshes/thigh.dae" scale="0.001 0.001 0.001"/>
      </geometry>
      <origin rpy="1.570796326794895 0.0 1.570796326794895" xyz="0.0 0.0 0.0"/>
    </visual>
    <collision>
      <geometry>
        <mesh filename="package://mini_project/meshes/thigh.dae" scale="0.001 0.001 0.001"/>
      </geometry>
      <origin rpy="1.570796326794895 0.0 1.570796326794895" xyz="0.0 0.0 0.0"/>
    </collision>
  </link>
  <gazebo reference="LH_leg_roll">
    <material>Gazebo/Orange</material>
  </gazebo>
  <link name="LH_upper_leg">
    <inertial>
      <origin rpy="1.570796326794895 0 1.570796326794895" xyz="-1.2465e-07 8.927e-08 -0.19777343169"/>
      <mass value="2.90604711841"/>
      <inertia ixx="0.07057863001314926" ixy="2.7932686e-10" ixz="-3.7129365e-10" iyy="0.07214686311642775" iyz="-6.9735152e-09" izz="0.0031329294799625"/>
    </inertial>
    <visual>
      <geometry>
        <mesh filename="package://mini_project/meshes/upper_leg.dae" scale="0.001 0.001 0.001"/>
      </geometry>
      <origin rpy="1.570796326794895 -1.570796326794895 0" xyz="0.0 0.0 0.0"/>
    </visual>
    <collision>
      <geometry>
        <mesh filename="package://mini_project/meshes/upper_leg.dae" scale="0.001 0.001 0.001"/>
      </geometry>
      <origin rpy="1.570796326794895 -1.570796326794895 0" xyz="0.0 0.0 0.0"/>
    </collision>
  </link>
  <gazebo reference="LH_upper_leg">
    <material>Gazebo/Green</material>
  </gazebo>
  <link name="LH_lower_leg">
    <inertial>
      <origin rpy="0 -0.2 0" xyz="-0.05466888228 2.713e-08 -0.15386388146"/>
      <mass value="1.81736381294"/>
      <inertia ixx="0.0907939555791539" ixy="-1.255242645e-08" ixz="0.01304754928405628" iyy="0.0951071480397549" iyz="-6.39667712e-09" izz="0.00552232540194871"/>
    </inertial>
    <visual>
      <geometry>
        <mesh filename="package://mini_project/meshes/lower_leg.dae" scale="0.001 0.001 0.001"/>
      </geometry>
      <origin rpy="1.570796326794895 1.370796326794895 0" xyz="0 0.0 0"/>
    </visual>
    <collision>
      <geometry>
        <mesh filename="package://mini_project/meshes/lower_leg.dae" scale="0.001 0.001 0.001"/>
      </geometry>
      <origin rpy="1.570796326794895 1.370796326794895 0" xyz="0 0.0 0"/>
    </collision>
  </link>
  <gazebo reference="LH_lower_leg">
    <kp>100000.0</kp>
    <kd>1.0</kd>
    <mu1>1.0</mu1>
    <mu2>1.0</mu2>
    <maxVel>0.0</maxVel>
    <minDepth>0.001</minDepth>
    <material>Gazebo/Red</material>
  </gazebo>
  <link name="LH_foot"/>
  <joint name="LH_hip_joint" type="revolute">
    <parent link="base_link"/>
    <child link="LH_leg_roll"/>
    <axis xyz="1.0 0.0 0.0"/>
    <origin xyz="-0.43 0.0 0.0"/>
    <limit effort="250" lower="-3.14159265358979" upper="3.14159265358979" velocity="5.0"/>
  </joint>
  <joint name="LH_upper_leg_joint" type="revolute">
    <parent link="LH_leg_roll"/>
    <child link="LH_upper_leg"/>
    <axis xyz="0.0 1.0  0.0"/>
    <origin xyz="0.0 0.233 0.0"/>
    <limit effort="250" lower="-3.14159265358979" upper="3.14159265358979" velocity="5.0"/>
  </joint>
  <joint name="LH_lower_leg_joint" type="revolute">
    <parent link="LH_upper_leg"/>
    <child link="LH_lower_leg"/>
    <axis xyz="0.0 1.0  0.0"/>
    <origin xyz="0.0 0.0 -0.45"/>
    <limit effort="250" lower="-3.14159265358979" upper="3.14159265358979" velocity="2.0"/>
  </joint>
  <joint name="LH_foot_joint" type="fixed">
    <parent link="LH_lower_leg"/>
    <child link="LH_foot"/>
    <origin xyz="0.0 0.0 -0.61"/>
  </joint>
  <gazebo reference="LH_hip_joint">
    <provideFeedback>true</provideFeedback>
  </gazebo>
  <gazebo reference="LH_upper_leg_joint">
    <provideFeedback>true</provideFeedback>
  </gazebo>
  <gazebo reference="LH_lower_leg_joint">
    <provideFeedback>true</provideFeedback>
  </gazebo>
  <transmission name="LH_hip_joint_trans">
    <type>transmission_interface/SimpleTransmission</type>
    <joint name="LH_hip_joint">
      <hardwareInterface>hardware_interface/EffortJointInterface</hardwareInterface>
    </joint>
    <actuator name="LH_hip_joint_motor">
      <mechanicalReduction>1</mechanicalReduction>
    </actuator>
  </transmission>
  <transmission name="LH_upper_leg_joint_trans">
    <type>transmission_interface/SimpleTransmission</type>
    <joint name="LH_upper_leg_joint">
      <hardwareInterface>hardware_interface/EffortJointInterface</hardwareInterface>
    </joint>
    <actuator name="LH_upper_leg_joint_motor">
      <mechanicalReduction>1</mechanicalReduction>
    </actuator>
  </transmission>
  <transmission name="LH_lower_leg_joint_trans">
    <type>transmission_interface/SimpleTransmission</type>
    <joint name="LH_lower_leg_joint">
      <hardwareInterface>hardware_interface/EffortJointInterface</hardwareInterface>
    </joint>
    <actuator name="LH_lower_joint_motor">
      <mechanicalReduction>1</mechanicalReduction>
    </actuator>
  </transmission>
  <link name="RH_leg_roll">
    <inertial>
      <origin rpy="0 0 0" xyz="-0.0016034699 -0.19560047521 0.0"/>
      <mass value="2.33840380361"/>
      <inertia ixx="0.01771591024567954" ixy="-0.00071891013320325" ixz="5.15073e-11" iyy="0.00540298667216859" iyz="1.6635487e-10" izz="0.01761332943089841"/>
    </inertial>
    <visual>
      <geometry>
        <mesh filename="package://mini_project/meshes/thigh.dae" scale="0.001 0.001 0.001"/>
      </geometry>
      <origin rpy="1.570796326794895 0.0 -1.570796326794895" xyz="0.0 0.0 0.0"/>
    </visual>
    <collision>
      <geometry>
        <mesh filename="package://mini_project/meshes/thigh.dae" scale="0.001 0.001 0.001"/>
      </geometry>
      <origin rpy="1.570796326794895 0.0 -1.570796326794895" xyz="0.0 0.0 0.0"/>
    </collision>
  </link>
  <gazebo reference="RH_leg_roll">
    <material>Gazebo/Orange</material>
  </gazebo>
  <link name="RH_upper_leg">
    <inertial>
      <origin rpy="1.570796326794895 0 1.570796326794895" xyz="-1.2465e-07 8.927e-08 -0.19777343169"/>
      <mass value="2.90604711841"/>
      <inertia ixx="0.07057863001314926" ixy="-2.7932686e-10" ixz="-3.7129365e-10" iyy="0.07214686311642775" iyz="6.9735152e-09" izz="0.0031329294799625"/>
    </inertial>
    <visual>
      <geometry>
        <mesh filename="package://mini_project/meshes/upper_leg.dae" scale="0.001 0.001 0.001"/>
      </geometry>
      <origin rpy="1.570796326794895 -1.570796326794895 0" xyz="0.0 0.0 0.0"/>
    </visual>
    <collision>
      <geometry>
        <mesh filename="package://mini_project/meshes/upper_leg.dae" scale="0.001 0.001 0.001"/>
      </geometry>
      <origin rpy="1.570796326794895 -1.570796326794895 0" xyz="0.0 0.0 0.0"/>
    </collision>
  </link>
  <gazebo reference="RH_upper_leg">
    <material>Gazebo/Green</material>
  </gazebo>
  <link name="RH_lower_leg">
    <inertial>
      <origin rpy="0 -0.2 0" xyz="-0.05466888228 2.713e-08 -0.15386388146"/>
      <mass value="1.81736381294"/>
      <inertia ixx="0.0907939555791539" ixy="-1.255242645e-08" ixz="0.01304754928405628" iyy="0.0951071480397549" iyz="-6.39667712e-09" izz="0.00552232540194871"/>
    </inertial>
    <visual>
      <geometry>
        <mesh filename="package://mini_project/meshes/lower_leg.dae" scale="0.001 0.001 0.001"/>
      </geometry>
      <origin rpy="1.570796326794895 1.370796326794895 0" xyz="0 0.0 0"/>
    </visual>
    <collision>
      <geometry>
        <mesh filename="package://mini_project/meshes/lower_leg.dae" scale="0.001 0.001 0.001"/>
      </geometry>
      <origin rpy="1.570796326794895 1.370796326794895 0" xyz="0 0.0 0"/>
    </collision>
  </link>
  <gazebo reference="RH_lower_leg">
    <kp>100000.0</kp>
    <kd>1.0</kd>
    <mu1>1.0</mu1>
    <mu2>1.0</mu2>
    <maxVel>0.0</maxVel>
    <minDepth>0.001</minDepth>
    <material>Gazebo/Red</material>
  </gazebo>
  <link name="RH_foot"/>
  <joint name="RH_hip_joint" type="revolute">
    <parent link="base_link"/>
    <child link="RH_leg_roll"/>
    <axis xyz="1.0 0.0 0.0"/>
    <origin xyz="-0.43 0.0 0.0"/>
    <limit effort="250" lower="-3.14159265358979" upper="3.14159265358979" velocity="5.0"/>
  </joint>
  <joint name="RH_upper_leg_joint" type="revolute">
    <parent link="RH_leg_roll"/>
    <child link="RH_upper_leg"/>
    <axis xyz="0.0 1.0  0.0"/>
    <origin xyz="0.0 -0.233 0.0"/>
    <limit effort="250" lower="-3.14159265358979" upper="3.14159265358979" velocity="5.0"/>
  </joint>
  <joint name="RH_lower_leg_joint" type="revolute">
    <parent link="RH_upper_leg"/>
    <child link="RH_lower_leg"/>
    <axis xyz="0.0 1.0  0.0"/>
    <origin xyz="0.0 0.0 -0.45"/>
    <limit effort="250" lower="-3.14159265358979" upper="3.14159265358979" velocity="2.0"/>
  </joint>
  <joint name="RH_foot_joint" type="fixed">
    <parent link="RH_lower_leg"/>
    <child link="RH_foot"/>
    <origin xyz="0.0 0.0 -0.61"/>
  </joint>
  <gazebo reference="RH_hip_joint">
    <provideFeedback>true</provideFeedback>
  </gazebo>
  <gazebo reference="RH_upper_leg_joint">
    <provideFeedback>true</provideFeedback>
  </gazebo>
  <gazebo reference="RH_lower_leg_joint">
    <provideFeedback>true</provideFeedback>
  </gazebo>
  <transmission name="RH_hip_joint_trans">
    <type>transmission_interface/SimpleTransmission</type>
    <joint name="RH_hip_joint">
      <hardwareInterface>hardware_interface/EffortJointInterface</hardwareInterface>
    </joint>
    <actuator name="RH_hip_joint_motor">
      <mechanicalReduction>1</mechanicalReduction>
    </actuator>
  </transmission>
  <transmission name="RH_upper_leg_joint_trans">
    <type>transmission_interface/SimpleTransmission</type>
    <joint name="RH_upper_leg_joint">
      <hardwareInterface>hardware_interface/EffortJointInterface</hardwareInterface>
    </joint>
    <actuator name="RH_upper_leg_joint_motor">
      <mechanicalReduction>1</mechanicalReduction>
    </actuator>
  </transmission>
  <transmission name="RH_lower_leg_joint_trans">
    <type>transmission_interface/SimpleTransmission</type>
    <joint name="RH_lower_leg_joint">
      <hardwareInterface>hardware_interface/EffortJointInterface</hardwareInterface>
    </joint>
    <actuator name="RH_lower_joint_motor">
      <mechanicalReduction>1</mechanicalReduction>
    </actuator>
  </transmission>
  <link name="manipulator_base">
    <inertial>
      <origin xyz="0.0001195 -0.01132600777 0.04996291284 "/>
      <mass value="1.63291158"/>
      <inertia ixx="0.00592368152307" ixy="0.0" ixz="0.0" iyy="0.00455222665474" iyz="0.0" izz="0.00630165344962"/>
    </inertial>
    <visual>
      <geometry>
        <mesh filename="package://mini_project/meshes/manipulator_joint.dae" scale="0.001 0.001 0.001"/>
      </geometry>
    </visual>
    <collision>
      <geometry>
        <mesh filename="package://mini_project/meshes/manipulator_joint.dae" scale="0.001 0.001 0.001"/>
      </geometry>
    </collision>
  </link>
  <link name="manipulator_segment_1">
    <inertial>
      <origin rpy="0 0.0 0" xyz="-0.12499144985 0.00000184653 0.0"/>
      <mass value="0.65721313"/>
      <inertia ixx="0.00029149081721" ixy="0.0" ixz="0.0" iyy="0.00745356022911" iyz="0.0" izz="0.0073062230739"/>
    </inertial>
    <visual>
      <geometry>
        <mesh filename="package://mini_project/meshes/manipulator_segment_1.dae" scale="0.001 0.001 0.001"/>
      </geometry>
      <origin rpy="1.570796326794895 0.0 3.14159265358979" xyz="0.0 0.0 0.0"/>
    </visual>
    <collision>
      <geometry>
        <mesh filename="package://mini_project/meshes/manipulator_segment_1.dae" scale="0.001 0.001 0.001"/>
      </geometry>
      <origin rpy="1.570796326794895 0.0 3.14159265358979" xyz="0.0 0.0 0.0"/>
    </collision>
  </link>
  <link name="manipulator_segment_2">
    <inertial>
      <origin rpy="0 0 0.0" xyz="0.19438946797 0.0 0.00000001267"/>
      <mass value="0.45716422"/>
      <inertia ixx="0.00016867187941" ixy="0.0" ixz="0.0" iyy="0.02041441059327" iyz="0.0" izz="0.02036185070001"/>
    </inertial>
    <visual>
      <geometry>
        <mesh filename="package://mini_project/meshes/manipulator_segment_2.dae" scale="0.001 0.001 0.001"/>
      </geometry>
      <origin rpy="1.570796326794895 3.14159265358979 0.0" xyz="0.0 0.0 0.0"/>
    </visual>
    <collision>
      <geometry>
        <mesh filename="package://mini_project/meshes/manipulator_segment_2.dae" scale="0.001 0.001 0.001"/>
      </geometry>
      <origin rpy="1.570796326794895 3.14159265358979 0.0" xyz="0.0 0.0 0.0"/>
    </collision>
  </link>
  <joint name="base_link_to_manipulator_base" type="fixed">
    <parent link="base_link"/>
    <child link="manipulator_base"/>
    <origin xyz="0.0 0.0 0.13"/>
  </joint>
  <joint name="manipulator_base_to_manipulator_segment_1" type="fixed">
    <parent link="manipulator_base"/>
    <child link="manipulator_segment_1"/>
    <origin rpy="0 0 0" xyz="0.0 0.04 0.075"/>
  </joint>
  <joint name="manipulator_segment_1_to_manipulator_segment_2" type="fixed">
    <parent link="manipulator_segment_1"/>
    <child link="manipulator_segment_2"/>
    <origin rpy="0.0 0.0 0.0" xyz="-0.25 -0.04 0.0"/>
  </joint>
  <gazebo>
    <plugin filename="libgazebo_ros_p3d.so" name="p3d_base_controller">
      <alwaysOn>true</alwaysOn>
      <updateRate>50.0</updateRate>
      <bodyName>base_link</bodyName>
      <topicName>odom/ground_truth</topicName>
      <gaussianNoise>0.001</gaussianNoise>
      <frameName>world</frameName>
      <xyzOffsets>0 0 0</xyzOffsets>
      <rpyOffsets>0 0 0</rpyOffsets>
    </plugin>
  </gazebo>
  <gazebo>
    <plugin filename="libgazebo_ros_control.so" name="gazebo_ros_control">
      <legacyModeNS>true</legacyModeNS>
    </plugin>
  </gazebo>
</robot>

